#VRML_SIM R2019a utf8
WorldInfo {
}
Viewpoint {
  orientation -0.9754643518180685 0.21240599517002962 0.057905021785547975 0.4037307621805622
  position 0.40030117649216773 2.0266601418424703 1.6800127759750134
}
TexturedBackground {
}
TexturedBackgroundLight {
}
Floor {
}
Solid {
  translation 0 0.5 0
  children [
    Shape {
      appearance PBRAppearance {
        baseColor 0 0 0
      }
      geometry Cylinder {
        height 1
        radius 0.15
      }
    }
    HingeJoint {
      jointParameters HingeJointParameters {
        axis 0 1 0
        anchor 0 0.15 0
      }
      endPoint Solid {
        translation 0.25 0.5099999999999999 -0.009999999999999997
        children [
          DEF G_table_2 Shape {
            appearance PBRAppearance {
              baseColor 0.8 0 0
            }
            geometry Box {
              size 0.5 0.01 0.1
            }
          }
          HingeJoint {
            jointParameters HingeJointParameters {
              axis 0 0 1
              anchor 0.25 0 0
              minStop -1
              maxStop 1
              springConstant 0.1
            }
            endPoint Solid {
              translation 0.3 0 0
              rotation 0 0 1 0
              children [
                DEF G_BOX2 Shape {
                  appearance PBRAppearance {
                    baseColor 0.3058823529411765 0.6039215686274509 0.023529411764705882
                  }
                  geometry Box {
                    size 0.1 0.01 0.1
                  }
                }
                HingeJoint {
                  jointParameters HingeJointParameters {
                    anchor 0.05 0 0
                  }
                  endPoint Solid {
                    translation 0.125 0 0
                    children [
                      DEF G_BOX_3 Shape {
                        appearance PBRAppearance {
                        }
                        geometry Box {
                          size 0.15 0.01 0.1
                        }
                      }
                    ]
                    boundingObject USE G_BOX_3
                    physics Physics {
                    }
                  }
                }
              ]
              boundingObject USE G_BOX2
              physics Physics {
              }
            }
          }
        ]
        boundingObject USE G_table_2
        physics Physics {
        }
      }
    }
  ]
}
